2025-06-03 11:00:03,366 INFO    MainThread:5024 [wandb_init.py:setup_run_log_directory():724] Logging user logs to C:\Users\Usuario\Trabajo Discretas pt2\wandb\run-20250603_110003-hdj24p7x\logs\debug.log
2025-06-03 11:00:03,366 INFO    MainThread:5024 [wandb_init.py:setup_run_log_directory():725] Logging internal logs to C:\Users\Usuario\Trabajo Discretas pt2\wandb\run-20250603_110003-hdj24p7x\logs\debug-internal.log
2025-06-03 11:00:03,366 INFO    MainThread:5024 [wandb_init.py:monkeypatch_ipython():643] configuring jupyter hooks <wandb.sdk.wandb_init._WandbInit object at 0x0000020DBFB8FA90>
2025-06-03 11:00:03,366 INFO    MainThread:5024 [wandb_init.py:init():852] calling init triggers
2025-06-03 11:00:03,367 INFO    MainThread:5024 [wandb_init.py:init():857] wandb.init called with sweep_config: {}
config: {'_wandb': {}}
2025-06-03 11:00:04,449 INFO    MainThread:5024 [wandb_init.py:init():893] starting backend
2025-06-03 11:00:04,449 INFO    MainThread:5024 [wandb_init.py:init():897] sending inform_init request
2025-06-03 11:00:04,452 INFO    MainThread:5024 [backend.py:_multiprocessing_setup():101] multiprocessing start_methods=spawn, using: spawn
2025-06-03 11:00:04,452 INFO    MainThread:5024 [wandb_init.py:init():907] backend started and connected
2025-06-03 11:00:04,454 INFO    MainThread:5024 [wandb_run.py:_label_probe_notebook():1376] probe notebook
2025-06-03 11:00:04,454 INFO    MainThread:5024 [wandb_run.py:_label_probe_notebook():1386] Unable to probe notebook: 'NoneType' object has no attribute 'get'
2025-06-03 11:00:04,454 INFO    MainThread:5024 [wandb_init.py:init():1005] updated telemetry
2025-06-03 11:00:04,513 INFO    MainThread:5024 [wandb_init.py:init():1029] communicating run to backend with 90.0 second timeout
2025-06-03 11:00:05,016 INFO    MainThread:5024 [wandb_init.py:init():1104] starting run threads in backend
2025-06-03 11:00:05,197 INFO    MainThread:5024 [wandb_run.py:_console_start():2573] atexit reg
2025-06-03 11:00:05,197 INFO    MainThread:5024 [wandb_run.py:_redirect():2421] redirect: wrap_raw
2025-06-03 11:00:05,197 INFO    MainThread:5024 [wandb_run.py:_redirect():2490] Wrapping output streams.
2025-06-03 11:00:05,197 INFO    MainThread:5024 [wandb_run.py:_redirect():2513] Redirects installed.
2025-06-03 11:00:05,198 INFO    MainThread:5024 [wandb_init.py:init():1150] run started, returning control to user process
2025-06-03 11:00:05,198 INFO    MainThread:5024 [wandb_run.py:_config_callback():1436] config_cb None None {'batch_size': 64, 'epochs': 20, 'device': 'cpu', 'hidden_dim': 152, 'lr': 0.001}
2025-06-03 11:10:41,169 WARNING MsgRouterThr:5024 [router.py:message_loop():63] [no run ID] message_loop has been closed
Traceback (most recent call last):
  File "C:\Anaconda3\envs\AntorchaPy\lib\site-packages\wandb\sdk\lib\sock_client.py", line 208, in _read_packet_bytes
    data = self._sock.recv(self._bufsize)
ConnectionResetError: [WinError 10054] An existing connection was forcibly closed by the remote host

The above exception was the direct cause of the following exception:

Traceback (most recent call last):
  File "C:\Anaconda3\envs\AntorchaPy\lib\site-packages\wandb\sdk\interface\router_sock.py", line 27, in _read_message
    return self._sock_client.read_server_response(timeout=1)
  File "C:\Anaconda3\envs\AntorchaPy\lib\site-packages\wandb\sdk\lib\sock_client.py", line 235, in read_server_response
    data = self._read_packet_bytes(timeout=timeout)
  File "C:\Anaconda3\envs\AntorchaPy\lib\site-packages\wandb\sdk\lib\sock_client.py", line 212, in _read_packet_bytes
    raise SockClientClosedError from e
wandb.sdk.lib.sock_client.SockClientClosedError

The above exception was the direct cause of the following exception:

Traceback (most recent call last):
  File "C:\Anaconda3\envs\AntorchaPy\lib\site-packages\wandb\sdk\interface\router.py", line 56, in message_loop
    msg = self._read_message()
  File "C:\Anaconda3\envs\AntorchaPy\lib\site-packages\wandb\sdk\interface\router_sock.py", line 29, in _read_message
    raise MessageRouterClosedError from e
wandb.sdk.interface.router.MessageRouterClosedError
2025-06-03 11:10:41,175 INFO    MsgRouterThr:5024 [mailbox.py:close():129] [no run ID] Closing mailbox, abandoning 7 handles.
2025-06-03 11:10:42,496 INFO    MainThread:5024 [wandb_init.py:_post_run_cell_hook():613] [no run ID] resuming backend
2025-06-03 11:10:42,496 ERROR   MainThread:5024 [redirect.py:_on_write():664] [no run ID] error in stdout callback
Traceback (most recent call last):
  File "C:\Anaconda3\envs\AntorchaPy\lib\site-packages\IPython\core\events.py", line 82, in trigger
    func(*args, **kwargs)
  File "C:\Anaconda3\envs\AntorchaPy\lib\site-packages\wandb\sdk\wandb_init.py", line 614, in _post_run_cell_hook
    self.backend.interface.publish_resume()
  File "C:\Anaconda3\envs\AntorchaPy\lib\site-packages\wandb\sdk\interface\interface.py", line 778, in publish_resume
    self._publish_resume(resume)
  File "C:\Anaconda3\envs\AntorchaPy\lib\site-packages\wandb\sdk\interface\interface_shared.py", line 293, in _publish_resume
    self._publish(rec)
  File "C:\Anaconda3\envs\AntorchaPy\lib\site-packages\wandb\sdk\interface\interface_sock.py", line 39, in _publish
    self._sock_client.send_record_publish(record)
  File "C:\Anaconda3\envs\AntorchaPy\lib\site-packages\wandb\sdk\lib\sock_client.py", line 174, in send_record_publish
    self.send_server_request(server_req)
  File "C:\Anaconda3\envs\AntorchaPy\lib\site-packages\wandb\sdk\lib\sock_client.py", line 154, in send_server_request
    self._send_message(msg)
  File "C:\Anaconda3\envs\AntorchaPy\lib\site-packages\wandb\sdk\lib\sock_client.py", line 151, in _send_message
    self._sendall_with_error_handle(header + data)
  File "C:\Anaconda3\envs\AntorchaPy\lib\site-packages\wandb\sdk\lib\sock_client.py", line 130, in _sendall_with_error_handle
    sent = self._sock.send(data)
ConnectionResetError: [WinError 10054] An existing connection was forcibly closed by the remote host

During handling of the above exception, another exception occurred:

Traceback (most recent call last):
  File "C:\Anaconda3\envs\AntorchaPy\lib\site-packages\wandb\sdk\lib\redirect.py", line 662, in _on_write
    cb(written_data)
  File "C:\Anaconda3\envs\AntorchaPy\lib\site-packages\wandb\sdk\wandb_run.py", line 2494, in <lambda>
    lambda data: self._console_raw_callback("stdout", data),
  File "C:\Anaconda3\envs\AntorchaPy\lib\site-packages\wandb\sdk\wandb_run.py", line 406, in wrapper
    return func(self, *args, **kwargs)
  File "C:\Anaconda3\envs\AntorchaPy\lib\site-packages\wandb\sdk\wandb_run.py", line 464, in wrapper_fn
    return func(self, *args, **kwargs)
  File "C:\Anaconda3\envs\AntorchaPy\lib\site-packages\wandb\sdk\wandb_run.py", line 1639, in _console_raw_callback
    self._backend.interface.publish_output_raw(name, data)
  File "C:\Anaconda3\envs\AntorchaPy\lib\site-packages\wandb\sdk\interface\interface.py", line 762, in publish_output_raw
    self._publish_output_raw(o)
  File "C:\Anaconda3\envs\AntorchaPy\lib\site-packages\wandb\sdk\interface\interface_shared.py", line 38, in _publish_output_raw
    self._publish(rec)
  File "C:\Anaconda3\envs\AntorchaPy\lib\site-packages\wandb\sdk\interface\interface_sock.py", line 39, in _publish
    self._sock_client.send_record_publish(record)
  File "C:\Anaconda3\envs\AntorchaPy\lib\site-packages\wandb\sdk\lib\sock_client.py", line 174, in send_record_publish
    self.send_server_request(server_req)
  File "C:\Anaconda3\envs\AntorchaPy\lib\site-packages\wandb\sdk\lib\sock_client.py", line 154, in send_server_request
    self._send_message(msg)
  File "C:\Anaconda3\envs\AntorchaPy\lib\site-packages\wandb\sdk\lib\sock_client.py", line 151, in _send_message
    self._sendall_with_error_handle(header + data)
  File "C:\Anaconda3\envs\AntorchaPy\lib\site-packages\wandb\sdk\lib\sock_client.py", line 130, in _sendall_with_error_handle
    sent = self._sock.send(data)
ConnectionResetError: [WinError 10054] An existing connection was forcibly closed by the remote host
2025-06-03 11:10:42,539 ERROR   MainThread:5024 [redirect.py:_on_write():664] [no run ID] error in stdout callback
Traceback (most recent call last):
  File "C:\Anaconda3\envs\AntorchaPy\lib\site-packages\IPython\core\events.py", line 82, in trigger
    func(*args, **kwargs)
  File "C:\Anaconda3\envs\AntorchaPy\lib\site-packages\wandb\sdk\wandb_init.py", line 614, in _post_run_cell_hook
    self.backend.interface.publish_resume()
  File "C:\Anaconda3\envs\AntorchaPy\lib\site-packages\wandb\sdk\interface\interface.py", line 778, in publish_resume
    self._publish_resume(resume)
  File "C:\Anaconda3\envs\AntorchaPy\lib\site-packages\wandb\sdk\interface\interface_shared.py", line 293, in _publish_resume
    self._publish(rec)
  File "C:\Anaconda3\envs\AntorchaPy\lib\site-packages\wandb\sdk\interface\interface_sock.py", line 39, in _publish
    self._sock_client.send_record_publish(record)
  File "C:\Anaconda3\envs\AntorchaPy\lib\site-packages\wandb\sdk\lib\sock_client.py", line 174, in send_record_publish
    self.send_server_request(server_req)
  File "C:\Anaconda3\envs\AntorchaPy\lib\site-packages\wandb\sdk\lib\sock_client.py", line 154, in send_server_request
    self._send_message(msg)
  File "C:\Anaconda3\envs\AntorchaPy\lib\site-packages\wandb\sdk\lib\sock_client.py", line 151, in _send_message
    self._sendall_with_error_handle(header + data)
  File "C:\Anaconda3\envs\AntorchaPy\lib\site-packages\wandb\sdk\lib\sock_client.py", line 130, in _sendall_with_error_handle
    sent = self._sock.send(data)
ConnectionResetError: [WinError 10054] An existing connection was forcibly closed by the remote host

During handling of the above exception, another exception occurred:

Traceback (most recent call last):
  File "C:\Anaconda3\envs\AntorchaPy\lib\site-packages\wandb\sdk\lib\redirect.py", line 662, in _on_write
    cb(written_data)
  File "C:\Anaconda3\envs\AntorchaPy\lib\site-packages\wandb\sdk\wandb_run.py", line 2494, in <lambda>
    lambda data: self._console_raw_callback("stdout", data),
  File "C:\Anaconda3\envs\AntorchaPy\lib\site-packages\wandb\sdk\wandb_run.py", line 406, in wrapper
    return func(self, *args, **kwargs)
  File "C:\Anaconda3\envs\AntorchaPy\lib\site-packages\wandb\sdk\wandb_run.py", line 464, in wrapper_fn
    return func(self, *args, **kwargs)
  File "C:\Anaconda3\envs\AntorchaPy\lib\site-packages\wandb\sdk\wandb_run.py", line 1639, in _console_raw_callback
    self._backend.interface.publish_output_raw(name, data)
  File "C:\Anaconda3\envs\AntorchaPy\lib\site-packages\wandb\sdk\interface\interface.py", line 762, in publish_output_raw
    self._publish_output_raw(o)
  File "C:\Anaconda3\envs\AntorchaPy\lib\site-packages\wandb\sdk\interface\interface_shared.py", line 38, in _publish_output_raw
    self._publish(rec)
  File "C:\Anaconda3\envs\AntorchaPy\lib\site-packages\wandb\sdk\interface\interface_sock.py", line 39, in _publish
    self._sock_client.send_record_publish(record)
  File "C:\Anaconda3\envs\AntorchaPy\lib\site-packages\wandb\sdk\lib\sock_client.py", line 174, in send_record_publish
    self.send_server_request(server_req)
  File "C:\Anaconda3\envs\AntorchaPy\lib\site-packages\wandb\sdk\lib\sock_client.py", line 154, in send_server_request
    self._send_message(msg)
  File "C:\Anaconda3\envs\AntorchaPy\lib\site-packages\wandb\sdk\lib\sock_client.py", line 151, in _send_message
    self._sendall_with_error_handle(header + data)
  File "C:\Anaconda3\envs\AntorchaPy\lib\site-packages\wandb\sdk\lib\sock_client.py", line 130, in _sendall_with_error_handle
    sent = self._sock.send(data)
ConnectionResetError: [WinError 10054] An existing connection was forcibly closed by the remote host
2025-06-03 11:10:42,900 ERROR   MainThread:5024 [redirect.py:_on_write():664] [no run ID] error in stderr callback
Traceback (most recent call last):
  File "C:\Anaconda3\envs\AntorchaPy\lib\site-packages\wandb\sdk\lib\redirect.py", line 662, in _on_write
    cb(written_data)
  File "C:\Anaconda3\envs\AntorchaPy\lib\site-packages\wandb\sdk\wandb_run.py", line 2500, in <lambda>
    lambda data: self._console_raw_callback("stderr", data),
  File "C:\Anaconda3\envs\AntorchaPy\lib\site-packages\wandb\sdk\wandb_run.py", line 406, in wrapper
    return func(self, *args, **kwargs)
  File "C:\Anaconda3\envs\AntorchaPy\lib\site-packages\wandb\sdk\wandb_run.py", line 464, in wrapper_fn
    return func(self, *args, **kwargs)
  File "C:\Anaconda3\envs\AntorchaPy\lib\site-packages\wandb\sdk\wandb_run.py", line 1639, in _console_raw_callback
    self._backend.interface.publish_output_raw(name, data)
  File "C:\Anaconda3\envs\AntorchaPy\lib\site-packages\wandb\sdk\interface\interface.py", line 762, in publish_output_raw
    self._publish_output_raw(o)
  File "C:\Anaconda3\envs\AntorchaPy\lib\site-packages\wandb\sdk\interface\interface_shared.py", line 38, in _publish_output_raw
    self._publish(rec)
  File "C:\Anaconda3\envs\AntorchaPy\lib\site-packages\wandb\sdk\interface\interface_sock.py", line 39, in _publish
    self._sock_client.send_record_publish(record)
  File "C:\Anaconda3\envs\AntorchaPy\lib\site-packages\wandb\sdk\lib\sock_client.py", line 174, in send_record_publish
    self.send_server_request(server_req)
  File "C:\Anaconda3\envs\AntorchaPy\lib\site-packages\wandb\sdk\lib\sock_client.py", line 154, in send_server_request
    self._send_message(msg)
  File "C:\Anaconda3\envs\AntorchaPy\lib\site-packages\wandb\sdk\lib\sock_client.py", line 151, in _send_message
    self._sendall_with_error_handle(header + data)
  File "C:\Anaconda3\envs\AntorchaPy\lib\site-packages\wandb\sdk\lib\sock_client.py", line 130, in _sendall_with_error_handle
    sent = self._sock.send(data)
ConnectionResetError: [WinError 10054] An existing connection was forcibly closed by the remote host
2025-06-03 11:10:42,901 ERROR   MainThread:5024 [redirect.py:_on_write():664] [no run ID] error in stderr callback
Traceback (most recent call last):
  File "C:\Anaconda3\envs\AntorchaPy\lib\site-packages\wandb\sdk\lib\redirect.py", line 662, in _on_write
    cb(written_data)
  File "C:\Anaconda3\envs\AntorchaPy\lib\site-packages\wandb\sdk\wandb_run.py", line 2500, in <lambda>
    lambda data: self._console_raw_callback("stderr", data),
  File "C:\Anaconda3\envs\AntorchaPy\lib\site-packages\wandb\sdk\wandb_run.py", line 406, in wrapper
    return func(self, *args, **kwargs)
  File "C:\Anaconda3\envs\AntorchaPy\lib\site-packages\wandb\sdk\wandb_run.py", line 464, in wrapper_fn
    return func(self, *args, **kwargs)
  File "C:\Anaconda3\envs\AntorchaPy\lib\site-packages\wandb\sdk\wandb_run.py", line 1639, in _console_raw_callback
    self._backend.interface.publish_output_raw(name, data)
  File "C:\Anaconda3\envs\AntorchaPy\lib\site-packages\wandb\sdk\interface\interface.py", line 762, in publish_output_raw
    self._publish_output_raw(o)
  File "C:\Anaconda3\envs\AntorchaPy\lib\site-packages\wandb\sdk\interface\interface_shared.py", line 38, in _publish_output_raw
    self._publish(rec)
  File "C:\Anaconda3\envs\AntorchaPy\lib\site-packages\wandb\sdk\interface\interface_sock.py", line 39, in _publish
    self._sock_client.send_record_publish(record)
  File "C:\Anaconda3\envs\AntorchaPy\lib\site-packages\wandb\sdk\lib\sock_client.py", line 174, in send_record_publish
    self.send_server_request(server_req)
  File "C:\Anaconda3\envs\AntorchaPy\lib\site-packages\wandb\sdk\lib\sock_client.py", line 154, in send_server_request
    self._send_message(msg)
  File "C:\Anaconda3\envs\AntorchaPy\lib\site-packages\wandb\sdk\lib\sock_client.py", line 151, in _send_message
    self._sendall_with_error_handle(header + data)
  File "C:\Anaconda3\envs\AntorchaPy\lib\site-packages\wandb\sdk\lib\sock_client.py", line 130, in _sendall_with_error_handle
    sent = self._sock.send(data)
ConnectionResetError: [WinError 10054] An existing connection was forcibly closed by the remote host
2025-06-03 11:10:42,902 ERROR   MainThread:5024 [redirect.py:_on_write():664] [no run ID] error in stderr callback
Traceback (most recent call last):
  File "C:\Anaconda3\envs\AntorchaPy\lib\site-packages\wandb\sdk\lib\redirect.py", line 662, in _on_write
    cb(written_data)
  File "C:\Anaconda3\envs\AntorchaPy\lib\site-packages\wandb\sdk\wandb_run.py", line 2500, in <lambda>
    lambda data: self._console_raw_callback("stderr", data),
  File "C:\Anaconda3\envs\AntorchaPy\lib\site-packages\wandb\sdk\wandb_run.py", line 406, in wrapper
    return func(self, *args, **kwargs)
  File "C:\Anaconda3\envs\AntorchaPy\lib\site-packages\wandb\sdk\wandb_run.py", line 464, in wrapper_fn
    return func(self, *args, **kwargs)
  File "C:\Anaconda3\envs\AntorchaPy\lib\site-packages\wandb\sdk\wandb_run.py", line 1639, in _console_raw_callback
    self._backend.interface.publish_output_raw(name, data)
  File "C:\Anaconda3\envs\AntorchaPy\lib\site-packages\wandb\sdk\interface\interface.py", line 762, in publish_output_raw
    self._publish_output_raw(o)
  File "C:\Anaconda3\envs\AntorchaPy\lib\site-packages\wandb\sdk\interface\interface_shared.py", line 38, in _publish_output_raw
    self._publish(rec)
  File "C:\Anaconda3\envs\AntorchaPy\lib\site-packages\wandb\sdk\interface\interface_sock.py", line 39, in _publish
    self._sock_client.send_record_publish(record)
  File "C:\Anaconda3\envs\AntorchaPy\lib\site-packages\wandb\sdk\lib\sock_client.py", line 174, in send_record_publish
    self.send_server_request(server_req)
  File "C:\Anaconda3\envs\AntorchaPy\lib\site-packages\wandb\sdk\lib\sock_client.py", line 154, in send_server_request
    self._send_message(msg)
  File "C:\Anaconda3\envs\AntorchaPy\lib\site-packages\wandb\sdk\lib\sock_client.py", line 151, in _send_message
    self._sendall_with_error_handle(header + data)
  File "C:\Anaconda3\envs\AntorchaPy\lib\site-packages\wandb\sdk\lib\sock_client.py", line 130, in _sendall_with_error_handle
    sent = self._sock.send(data)
ConnectionResetError: [WinError 10054] An existing connection was forcibly closed by the remote host
2025-06-03 11:10:42,903 ERROR   MainThread:5024 [redirect.py:_on_write():664] [no run ID] error in stderr callback
Traceback (most recent call last):
  File "C:\Anaconda3\envs\AntorchaPy\lib\site-packages\wandb\sdk\lib\redirect.py", line 662, in _on_write
    cb(written_data)
  File "C:\Anaconda3\envs\AntorchaPy\lib\site-packages\wandb\sdk\wandb_run.py", line 2500, in <lambda>
    lambda data: self._console_raw_callback("stderr", data),
  File "C:\Anaconda3\envs\AntorchaPy\lib\site-packages\wandb\sdk\wandb_run.py", line 406, in wrapper
    return func(self, *args, **kwargs)
  File "C:\Anaconda3\envs\AntorchaPy\lib\site-packages\wandb\sdk\wandb_run.py", line 464, in wrapper_fn
    return func(self, *args, **kwargs)
  File "C:\Anaconda3\envs\AntorchaPy\lib\site-packages\wandb\sdk\wandb_run.py", line 1639, in _console_raw_callback
    self._backend.interface.publish_output_raw(name, data)
  File "C:\Anaconda3\envs\AntorchaPy\lib\site-packages\wandb\sdk\interface\interface.py", line 762, in publish_output_raw
    self._publish_output_raw(o)
  File "C:\Anaconda3\envs\AntorchaPy\lib\site-packages\wandb\sdk\interface\interface_shared.py", line 38, in _publish_output_raw
    self._publish(rec)
  File "C:\Anaconda3\envs\AntorchaPy\lib\site-packages\wandb\sdk\interface\interface_sock.py", line 39, in _publish
    self._sock_client.send_record_publish(record)
  File "C:\Anaconda3\envs\AntorchaPy\lib\site-packages\wandb\sdk\lib\sock_client.py", line 174, in send_record_publish
    self.send_server_request(server_req)
  File "C:\Anaconda3\envs\AntorchaPy\lib\site-packages\wandb\sdk\lib\sock_client.py", line 154, in send_server_request
    self._send_message(msg)
  File "C:\Anaconda3\envs\AntorchaPy\lib\site-packages\wandb\sdk\lib\sock_client.py", line 151, in _send_message
    self._sendall_with_error_handle(header + data)
  File "C:\Anaconda3\envs\AntorchaPy\lib\site-packages\wandb\sdk\lib\sock_client.py", line 130, in _sendall_with_error_handle
    sent = self._sock.send(data)
ConnectionResetError: [WinError 10054] An existing connection was forcibly closed by the remote host
2025-06-03 11:10:42,904 ERROR   MainThread:5024 [redirect.py:_on_write():664] [no run ID] error in stderr callback
Traceback (most recent call last):
  File "C:\Anaconda3\envs\AntorchaPy\lib\site-packages\wandb\sdk\lib\redirect.py", line 662, in _on_write
    cb(written_data)
  File "C:\Anaconda3\envs\AntorchaPy\lib\site-packages\wandb\sdk\wandb_run.py", line 2500, in <lambda>
    lambda data: self._console_raw_callback("stderr", data),
  File "C:\Anaconda3\envs\AntorchaPy\lib\site-packages\wandb\sdk\wandb_run.py", line 406, in wrapper
    return func(self, *args, **kwargs)
  File "C:\Anaconda3\envs\AntorchaPy\lib\site-packages\wandb\sdk\wandb_run.py", line 464, in wrapper_fn
    return func(self, *args, **kwargs)
  File "C:\Anaconda3\envs\AntorchaPy\lib\site-packages\wandb\sdk\wandb_run.py", line 1639, in _console_raw_callback
    self._backend.interface.publish_output_raw(name, data)
  File "C:\Anaconda3\envs\AntorchaPy\lib\site-packages\wandb\sdk\interface\interface.py", line 762, in publish_output_raw
    self._publish_output_raw(o)
  File "C:\Anaconda3\envs\AntorchaPy\lib\site-packages\wandb\sdk\interface\interface_shared.py", line 38, in _publish_output_raw
    self._publish(rec)
  File "C:\Anaconda3\envs\AntorchaPy\lib\site-packages\wandb\sdk\interface\interface_sock.py", line 39, in _publish
    self._sock_client.send_record_publish(record)
  File "C:\Anaconda3\envs\AntorchaPy\lib\site-packages\wandb\sdk\lib\sock_client.py", line 174, in send_record_publish
    self.send_server_request(server_req)
  File "C:\Anaconda3\envs\AntorchaPy\lib\site-packages\wandb\sdk\lib\sock_client.py", line 154, in send_server_request
    self._send_message(msg)
  File "C:\Anaconda3\envs\AntorchaPy\lib\site-packages\wandb\sdk\lib\sock_client.py", line 151, in _send_message
    self._sendall_with_error_handle(header + data)
  File "C:\Anaconda3\envs\AntorchaPy\lib\site-packages\wandb\sdk\lib\sock_client.py", line 130, in _sendall_with_error_handle
    sent = self._sock.send(data)
ConnectionResetError: [WinError 10054] An existing connection was forcibly closed by the remote host
2025-06-03 11:10:42,905 ERROR   MainThread:5024 [redirect.py:_on_write():664] [no run ID] error in stderr callback
Traceback (most recent call last):
  File "C:\Anaconda3\envs\AntorchaPy\lib\site-packages\wandb\sdk\lib\redirect.py", line 662, in _on_write
    cb(written_data)
  File "C:\Anaconda3\envs\AntorchaPy\lib\site-packages\wandb\sdk\wandb_run.py", line 2500, in <lambda>
    lambda data: self._console_raw_callback("stderr", data),
  File "C:\Anaconda3\envs\AntorchaPy\lib\site-packages\wandb\sdk\wandb_run.py", line 406, in wrapper
    return func(self, *args, **kwargs)
  File "C:\Anaconda3\envs\AntorchaPy\lib\site-packages\wandb\sdk\wandb_run.py", line 464, in wrapper_fn
    return func(self, *args, **kwargs)
  File "C:\Anaconda3\envs\AntorchaPy\lib\site-packages\wandb\sdk\wandb_run.py", line 1639, in _console_raw_callback
    self._backend.interface.publish_output_raw(name, data)
  File "C:\Anaconda3\envs\AntorchaPy\lib\site-packages\wandb\sdk\interface\interface.py", line 762, in publish_output_raw
    self._publish_output_raw(o)
  File "C:\Anaconda3\envs\AntorchaPy\lib\site-packages\wandb\sdk\interface\interface_shared.py", line 38, in _publish_output_raw
    self._publish(rec)
  File "C:\Anaconda3\envs\AntorchaPy\lib\site-packages\wandb\sdk\interface\interface_sock.py", line 39, in _publish
    self._sock_client.send_record_publish(record)
  File "C:\Anaconda3\envs\AntorchaPy\lib\site-packages\wandb\sdk\lib\sock_client.py", line 174, in send_record_publish
    self.send_server_request(server_req)
  File "C:\Anaconda3\envs\AntorchaPy\lib\site-packages\wandb\sdk\lib\sock_client.py", line 154, in send_server_request
    self._send_message(msg)
  File "C:\Anaconda3\envs\AntorchaPy\lib\site-packages\wandb\sdk\lib\sock_client.py", line 151, in _send_message
    self._sendall_with_error_handle(header + data)
  File "C:\Anaconda3\envs\AntorchaPy\lib\site-packages\wandb\sdk\lib\sock_client.py", line 130, in _sendall_with_error_handle
    sent = self._sock.send(data)
ConnectionResetError: [WinError 10054] An existing connection was forcibly closed by the remote host
2025-06-03 11:10:42,906 ERROR   MainThread:5024 [redirect.py:_on_write():664] [no run ID] error in stderr callback
Traceback (most recent call last):
  File "C:\Anaconda3\envs\AntorchaPy\lib\site-packages\wandb\sdk\lib\redirect.py", line 662, in _on_write
    cb(written_data)
  File "C:\Anaconda3\envs\AntorchaPy\lib\site-packages\wandb\sdk\wandb_run.py", line 2500, in <lambda>
    lambda data: self._console_raw_callback("stderr", data),
  File "C:\Anaconda3\envs\AntorchaPy\lib\site-packages\wandb\sdk\wandb_run.py", line 406, in wrapper
    return func(self, *args, **kwargs)
  File "C:\Anaconda3\envs\AntorchaPy\lib\site-packages\wandb\sdk\wandb_run.py", line 464, in wrapper_fn
    return func(self, *args, **kwargs)
  File "C:\Anaconda3\envs\AntorchaPy\lib\site-packages\wandb\sdk\wandb_run.py", line 1639, in _console_raw_callback
    self._backend.interface.publish_output_raw(name, data)
  File "C:\Anaconda3\envs\AntorchaPy\lib\site-packages\wandb\sdk\interface\interface.py", line 762, in publish_output_raw
    self._publish_output_raw(o)
  File "C:\Anaconda3\envs\AntorchaPy\lib\site-packages\wandb\sdk\interface\interface_shared.py", line 38, in _publish_output_raw
    self._publish(rec)
  File "C:\Anaconda3\envs\AntorchaPy\lib\site-packages\wandb\sdk\interface\interface_sock.py", line 39, in _publish
    self._sock_client.send_record_publish(record)
  File "C:\Anaconda3\envs\AntorchaPy\lib\site-packages\wandb\sdk\lib\sock_client.py", line 174, in send_record_publish
    self.send_server_request(server_req)
  File "C:\Anaconda3\envs\AntorchaPy\lib\site-packages\wandb\sdk\lib\sock_client.py", line 154, in send_server_request
    self._send_message(msg)
  File "C:\Anaconda3\envs\AntorchaPy\lib\site-packages\wandb\sdk\lib\sock_client.py", line 151, in _send_message
    self._sendall_with_error_handle(header + data)
  File "C:\Anaconda3\envs\AntorchaPy\lib\site-packages\wandb\sdk\lib\sock_client.py", line 130, in _sendall_with_error_handle
    sent = self._sock.send(data)
ConnectionResetError: [WinError 10054] An existing connection was forcibly closed by the remote host
2025-06-03 11:10:42,907 ERROR   MainThread:5024 [redirect.py:_on_write():664] [no run ID] error in stderr callback
Traceback (most recent call last):
  File "C:\Anaconda3\envs\AntorchaPy\lib\site-packages\wandb\sdk\lib\redirect.py", line 662, in _on_write
    cb(written_data)
  File "C:\Anaconda3\envs\AntorchaPy\lib\site-packages\wandb\sdk\wandb_run.py", line 2500, in <lambda>
    lambda data: self._console_raw_callback("stderr", data),
  File "C:\Anaconda3\envs\AntorchaPy\lib\site-packages\wandb\sdk\wandb_run.py", line 406, in wrapper
    return func(self, *args, **kwargs)
  File "C:\Anaconda3\envs\AntorchaPy\lib\site-packages\wandb\sdk\wandb_run.py", line 464, in wrapper_fn
    return func(self, *args, **kwargs)
  File "C:\Anaconda3\envs\AntorchaPy\lib\site-packages\wandb\sdk\wandb_run.py", line 1639, in _console_raw_callback
    self._backend.interface.publish_output_raw(name, data)
  File "C:\Anaconda3\envs\AntorchaPy\lib\site-packages\wandb\sdk\interface\interface.py", line 762, in publish_output_raw
    self._publish_output_raw(o)
  File "C:\Anaconda3\envs\AntorchaPy\lib\site-packages\wandb\sdk\interface\interface_shared.py", line 38, in _publish_output_raw
    self._publish(rec)
  File "C:\Anaconda3\envs\AntorchaPy\lib\site-packages\wandb\sdk\interface\interface_sock.py", line 39, in _publish
    self._sock_client.send_record_publish(record)
  File "C:\Anaconda3\envs\AntorchaPy\lib\site-packages\wandb\sdk\lib\sock_client.py", line 174, in send_record_publish
    self.send_server_request(server_req)
  File "C:\Anaconda3\envs\AntorchaPy\lib\site-packages\wandb\sdk\lib\sock_client.py", line 154, in send_server_request
    self._send_message(msg)
  File "C:\Anaconda3\envs\AntorchaPy\lib\site-packages\wandb\sdk\lib\sock_client.py", line 151, in _send_message
    self._sendall_with_error_handle(header + data)
  File "C:\Anaconda3\envs\AntorchaPy\lib\site-packages\wandb\sdk\lib\sock_client.py", line 130, in _sendall_with_error_handle
    sent = self._sock.send(data)
ConnectionResetError: [WinError 10054] An existing connection was forcibly closed by the remote host
2025-06-03 11:10:42,908 ERROR   MainThread:5024 [redirect.py:_on_write():664] [no run ID] error in stderr callback
Traceback (most recent call last):
  File "C:\Anaconda3\envs\AntorchaPy\lib\site-packages\wandb\sdk\lib\redirect.py", line 662, in _on_write
    cb(written_data)
  File "C:\Anaconda3\envs\AntorchaPy\lib\site-packages\wandb\sdk\wandb_run.py", line 2500, in <lambda>
    lambda data: self._console_raw_callback("stderr", data),
  File "C:\Anaconda3\envs\AntorchaPy\lib\site-packages\wandb\sdk\wandb_run.py", line 406, in wrapper
    return func(self, *args, **kwargs)
  File "C:\Anaconda3\envs\AntorchaPy\lib\site-packages\wandb\sdk\wandb_run.py", line 464, in wrapper_fn
    return func(self, *args, **kwargs)
  File "C:\Anaconda3\envs\AntorchaPy\lib\site-packages\wandb\sdk\wandb_run.py", line 1639, in _console_raw_callback
    self._backend.interface.publish_output_raw(name, data)
  File "C:\Anaconda3\envs\AntorchaPy\lib\site-packages\wandb\sdk\interface\interface.py", line 762, in publish_output_raw
    self._publish_output_raw(o)
  File "C:\Anaconda3\envs\AntorchaPy\lib\site-packages\wandb\sdk\interface\interface_shared.py", line 38, in _publish_output_raw
    self._publish(rec)
  File "C:\Anaconda3\envs\AntorchaPy\lib\site-packages\wandb\sdk\interface\interface_sock.py", line 39, in _publish
    self._sock_client.send_record_publish(record)
  File "C:\Anaconda3\envs\AntorchaPy\lib\site-packages\wandb\sdk\lib\sock_client.py", line 174, in send_record_publish
    self.send_server_request(server_req)
  File "C:\Anaconda3\envs\AntorchaPy\lib\site-packages\wandb\sdk\lib\sock_client.py", line 154, in send_server_request
    self._send_message(msg)
  File "C:\Anaconda3\envs\AntorchaPy\lib\site-packages\wandb\sdk\lib\sock_client.py", line 151, in _send_message
    self._sendall_with_error_handle(header + data)
  File "C:\Anaconda3\envs\AntorchaPy\lib\site-packages\wandb\sdk\lib\sock_client.py", line 130, in _sendall_with_error_handle
    sent = self._sock.send(data)
ConnectionResetError: [WinError 10054] An existing connection was forcibly closed by the remote host
2025-06-03 11:10:42,908 ERROR   MainThread:5024 [redirect.py:_on_write():664] [no run ID] error in stderr callback
Traceback (most recent call last):
  File "C:\Anaconda3\envs\AntorchaPy\lib\site-packages\wandb\sdk\lib\redirect.py", line 662, in _on_write
    cb(written_data)
  File "C:\Anaconda3\envs\AntorchaPy\lib\site-packages\wandb\sdk\wandb_run.py", line 2500, in <lambda>
    lambda data: self._console_raw_callback("stderr", data),
  File "C:\Anaconda3\envs\AntorchaPy\lib\site-packages\wandb\sdk\wandb_run.py", line 406, in wrapper
    return func(self, *args, **kwargs)
  File "C:\Anaconda3\envs\AntorchaPy\lib\site-packages\wandb\sdk\wandb_run.py", line 464, in wrapper_fn
    return func(self, *args, **kwargs)
  File "C:\Anaconda3\envs\AntorchaPy\lib\site-packages\wandb\sdk\wandb_run.py", line 1639, in _console_raw_callback
    self._backend.interface.publish_output_raw(name, data)
  File "C:\Anaconda3\envs\AntorchaPy\lib\site-packages\wandb\sdk\interface\interface.py", line 762, in publish_output_raw
    self._publish_output_raw(o)
  File "C:\Anaconda3\envs\AntorchaPy\lib\site-packages\wandb\sdk\interface\interface_shared.py", line 38, in _publish_output_raw
    self._publish(rec)
  File "C:\Anaconda3\envs\AntorchaPy\lib\site-packages\wandb\sdk\interface\interface_sock.py", line 39, in _publish
    self._sock_client.send_record_publish(record)
  File "C:\Anaconda3\envs\AntorchaPy\lib\site-packages\wandb\sdk\lib\sock_client.py", line 174, in send_record_publish
    self.send_server_request(server_req)
  File "C:\Anaconda3\envs\AntorchaPy\lib\site-packages\wandb\sdk\lib\sock_client.py", line 154, in send_server_request
    self._send_message(msg)
  File "C:\Anaconda3\envs\AntorchaPy\lib\site-packages\wandb\sdk\lib\sock_client.py", line 151, in _send_message
    self._sendall_with_error_handle(header + data)
  File "C:\Anaconda3\envs\AntorchaPy\lib\site-packages\wandb\sdk\lib\sock_client.py", line 130, in _sendall_with_error_handle
    sent = self._sock.send(data)
ConnectionResetError: [WinError 10054] An existing connection was forcibly closed by the remote host
2025-06-03 11:10:42,909 ERROR   MainThread:5024 [redirect.py:_on_write():664] [no run ID] error in stderr callback
Traceback (most recent call last):
  File "C:\Anaconda3\envs\AntorchaPy\lib\site-packages\wandb\sdk\lib\redirect.py", line 662, in _on_write
    cb(written_data)
  File "C:\Anaconda3\envs\AntorchaPy\lib\site-packages\wandb\sdk\wandb_run.py", line 2500, in <lambda>
    lambda data: self._console_raw_callback("stderr", data),
  File "C:\Anaconda3\envs\AntorchaPy\lib\site-packages\wandb\sdk\wandb_run.py", line 406, in wrapper
    return func(self, *args, **kwargs)
  File "C:\Anaconda3\envs\AntorchaPy\lib\site-packages\wandb\sdk\wandb_run.py", line 464, in wrapper_fn
    return func(self, *args, **kwargs)
  File "C:\Anaconda3\envs\AntorchaPy\lib\site-packages\wandb\sdk\wandb_run.py", line 1639, in _console_raw_callback
    self._backend.interface.publish_output_raw(name, data)
  File "C:\Anaconda3\envs\AntorchaPy\lib\site-packages\wandb\sdk\interface\interface.py", line 762, in publish_output_raw
    self._publish_output_raw(o)
  File "C:\Anaconda3\envs\AntorchaPy\lib\site-packages\wandb\sdk\interface\interface_shared.py", line 38, in _publish_output_raw
    self._publish(rec)
  File "C:\Anaconda3\envs\AntorchaPy\lib\site-packages\wandb\sdk\interface\interface_sock.py", line 39, in _publish
    self._sock_client.send_record_publish(record)
  File "C:\Anaconda3\envs\AntorchaPy\lib\site-packages\wandb\sdk\lib\sock_client.py", line 174, in send_record_publish
    self.send_server_request(server_req)
  File "C:\Anaconda3\envs\AntorchaPy\lib\site-packages\wandb\sdk\lib\sock_client.py", line 154, in send_server_request
    self._send_message(msg)
  File "C:\Anaconda3\envs\AntorchaPy\lib\site-packages\wandb\sdk\lib\sock_client.py", line 151, in _send_message
    self._sendall_with_error_handle(header + data)
  File "C:\Anaconda3\envs\AntorchaPy\lib\site-packages\wandb\sdk\lib\sock_client.py", line 130, in _sendall_with_error_handle
    sent = self._sock.send(data)
ConnectionResetError: [WinError 10054] An existing connection was forcibly closed by the remote host
2025-06-03 11:10:42,910 ERROR   MainThread:5024 [redirect.py:_on_write():664] [no run ID] error in stderr callback
Traceback (most recent call last):
  File "C:\Anaconda3\envs\AntorchaPy\lib\site-packages\wandb\sdk\lib\redirect.py", line 662, in _on_write
    cb(written_data)
  File "C:\Anaconda3\envs\AntorchaPy\lib\site-packages\wandb\sdk\wandb_run.py", line 2500, in <lambda>
    lambda data: self._console_raw_callback("stderr", data),
  File "C:\Anaconda3\envs\AntorchaPy\lib\site-packages\wandb\sdk\wandb_run.py", line 406, in wrapper
    return func(self, *args, **kwargs)
  File "C:\Anaconda3\envs\AntorchaPy\lib\site-packages\wandb\sdk\wandb_run.py", line 464, in wrapper_fn
    return func(self, *args, **kwargs)
  File "C:\Anaconda3\envs\AntorchaPy\lib\site-packages\wandb\sdk\wandb_run.py", line 1639, in _console_raw_callback
    self._backend.interface.publish_output_raw(name, data)
  File "C:\Anaconda3\envs\AntorchaPy\lib\site-packages\wandb\sdk\interface\interface.py", line 762, in publish_output_raw
    self._publish_output_raw(o)
  File "C:\Anaconda3\envs\AntorchaPy\lib\site-packages\wandb\sdk\interface\interface_shared.py", line 38, in _publish_output_raw
    self._publish(rec)
  File "C:\Anaconda3\envs\AntorchaPy\lib\site-packages\wandb\sdk\interface\interface_sock.py", line 39, in _publish
    self._sock_client.send_record_publish(record)
  File "C:\Anaconda3\envs\AntorchaPy\lib\site-packages\wandb\sdk\lib\sock_client.py", line 174, in send_record_publish
    self.send_server_request(server_req)
  File "C:\Anaconda3\envs\AntorchaPy\lib\site-packages\wandb\sdk\lib\sock_client.py", line 154, in send_server_request
    self._send_message(msg)
  File "C:\Anaconda3\envs\AntorchaPy\lib\site-packages\wandb\sdk\lib\sock_client.py", line 151, in _send_message
    self._sendall_with_error_handle(header + data)
  File "C:\Anaconda3\envs\AntorchaPy\lib\site-packages\wandb\sdk\lib\sock_client.py", line 130, in _sendall_with_error_handle
    sent = self._sock.send(data)
ConnectionResetError: [WinError 10054] An existing connection was forcibly closed by the remote host
2025-06-03 11:10:42,911 ERROR   MainThread:5024 [redirect.py:_on_write():664] [no run ID] error in stderr callback
Traceback (most recent call last):
  File "C:\Anaconda3\envs\AntorchaPy\lib\site-packages\wandb\sdk\lib\redirect.py", line 662, in _on_write
    cb(written_data)
  File "C:\Anaconda3\envs\AntorchaPy\lib\site-packages\wandb\sdk\wandb_run.py", line 2500, in <lambda>
    lambda data: self._console_raw_callback("stderr", data),
  File "C:\Anaconda3\envs\AntorchaPy\lib\site-packages\wandb\sdk\wandb_run.py", line 406, in wrapper
    return func(self, *args, **kwargs)
  File "C:\Anaconda3\envs\AntorchaPy\lib\site-packages\wandb\sdk\wandb_run.py", line 464, in wrapper_fn
    return func(self, *args, **kwargs)
  File "C:\Anaconda3\envs\AntorchaPy\lib\site-packages\wandb\sdk\wandb_run.py", line 1639, in _console_raw_callback
    self._backend.interface.publish_output_raw(name, data)
  File "C:\Anaconda3\envs\AntorchaPy\lib\site-packages\wandb\sdk\interface\interface.py", line 762, in publish_output_raw
    self._publish_output_raw(o)
  File "C:\Anaconda3\envs\AntorchaPy\lib\site-packages\wandb\sdk\interface\interface_shared.py", line 38, in _publish_output_raw
    self._publish(rec)
  File "C:\Anaconda3\envs\AntorchaPy\lib\site-packages\wandb\sdk\interface\interface_sock.py", line 39, in _publish
    self._sock_client.send_record_publish(record)
  File "C:\Anaconda3\envs\AntorchaPy\lib\site-packages\wandb\sdk\lib\sock_client.py", line 174, in send_record_publish
    self.send_server_request(server_req)
  File "C:\Anaconda3\envs\AntorchaPy\lib\site-packages\wandb\sdk\lib\sock_client.py", line 154, in send_server_request
    self._send_message(msg)
  File "C:\Anaconda3\envs\AntorchaPy\lib\site-packages\wandb\sdk\lib\sock_client.py", line 151, in _send_message
    self._sendall_with_error_handle(header + data)
  File "C:\Anaconda3\envs\AntorchaPy\lib\site-packages\wandb\sdk\lib\sock_client.py", line 130, in _sendall_with_error_handle
    sent = self._sock.send(data)
ConnectionResetError: [WinError 10054] An existing connection was forcibly closed by the remote host
2025-06-03 11:10:42,912 ERROR   MainThread:5024 [redirect.py:_on_write():664] [no run ID] error in stderr callback
Traceback (most recent call last):
  File "C:\Anaconda3\envs\AntorchaPy\lib\site-packages\wandb\sdk\lib\redirect.py", line 662, in _on_write
    cb(written_data)
  File "C:\Anaconda3\envs\AntorchaPy\lib\site-packages\wandb\sdk\wandb_run.py", line 2500, in <lambda>
    lambda data: self._console_raw_callback("stderr", data),
  File "C:\Anaconda3\envs\AntorchaPy\lib\site-packages\wandb\sdk\wandb_run.py", line 406, in wrapper
    return func(self, *args, **kwargs)
  File "C:\Anaconda3\envs\AntorchaPy\lib\site-packages\wandb\sdk\wandb_run.py", line 464, in wrapper_fn
    return func(self, *args, **kwargs)
  File "C:\Anaconda3\envs\AntorchaPy\lib\site-packages\wandb\sdk\wandb_run.py", line 1639, in _console_raw_callback
    self._backend.interface.publish_output_raw(name, data)
  File "C:\Anaconda3\envs\AntorchaPy\lib\site-packages\wandb\sdk\interface\interface.py", line 762, in publish_output_raw
    self._publish_output_raw(o)
  File "C:\Anaconda3\envs\AntorchaPy\lib\site-packages\wandb\sdk\interface\interface_shared.py", line 38, in _publish_output_raw
    self._publish(rec)
  File "C:\Anaconda3\envs\AntorchaPy\lib\site-packages\wandb\sdk\interface\interface_sock.py", line 39, in _publish
    self._sock_client.send_record_publish(record)
  File "C:\Anaconda3\envs\AntorchaPy\lib\site-packages\wandb\sdk\lib\sock_client.py", line 174, in send_record_publish
    self.send_server_request(server_req)
  File "C:\Anaconda3\envs\AntorchaPy\lib\site-packages\wandb\sdk\lib\sock_client.py", line 154, in send_server_request
    self._send_message(msg)
  File "C:\Anaconda3\envs\AntorchaPy\lib\site-packages\wandb\sdk\lib\sock_client.py", line 151, in _send_message
    self._sendall_with_error_handle(header + data)
  File "C:\Anaconda3\envs\AntorchaPy\lib\site-packages\wandb\sdk\lib\sock_client.py", line 130, in _sendall_with_error_handle
    sent = self._sock.send(data)
ConnectionResetError: [WinError 10054] An existing connection was forcibly closed by the remote host
2025-06-03 11:10:42,913 ERROR   MainThread:5024 [redirect.py:_on_write():664] [no run ID] error in stderr callback
Traceback (most recent call last):
  File "C:\Anaconda3\envs\AntorchaPy\lib\site-packages\wandb\sdk\lib\redirect.py", line 662, in _on_write
    cb(written_data)
  File "C:\Anaconda3\envs\AntorchaPy\lib\site-packages\wandb\sdk\wandb_run.py", line 2500, in <lambda>
    lambda data: self._console_raw_callback("stderr", data),
  File "C:\Anaconda3\envs\AntorchaPy\lib\site-packages\wandb\sdk\wandb_run.py", line 406, in wrapper
    return func(self, *args, **kwargs)
  File "C:\Anaconda3\envs\AntorchaPy\lib\site-packages\wandb\sdk\wandb_run.py", line 464, in wrapper_fn
    return func(self, *args, **kwargs)
  File "C:\Anaconda3\envs\AntorchaPy\lib\site-packages\wandb\sdk\wandb_run.py", line 1639, in _console_raw_callback
    self._backend.interface.publish_output_raw(name, data)
  File "C:\Anaconda3\envs\AntorchaPy\lib\site-packages\wandb\sdk\interface\interface.py", line 762, in publish_output_raw
    self._publish_output_raw(o)
  File "C:\Anaconda3\envs\AntorchaPy\lib\site-packages\wandb\sdk\interface\interface_shared.py", line 38, in _publish_output_raw
    self._publish(rec)
  File "C:\Anaconda3\envs\AntorchaPy\lib\site-packages\wandb\sdk\interface\interface_sock.py", line 39, in _publish
    self._sock_client.send_record_publish(record)
  File "C:\Anaconda3\envs\AntorchaPy\lib\site-packages\wandb\sdk\lib\sock_client.py", line 174, in send_record_publish
    self.send_server_request(server_req)
  File "C:\Anaconda3\envs\AntorchaPy\lib\site-packages\wandb\sdk\lib\sock_client.py", line 154, in send_server_request
    self._send_message(msg)
  File "C:\Anaconda3\envs\AntorchaPy\lib\site-packages\wandb\sdk\lib\sock_client.py", line 151, in _send_message
    self._sendall_with_error_handle(header + data)
  File "C:\Anaconda3\envs\AntorchaPy\lib\site-packages\wandb\sdk\lib\sock_client.py", line 130, in _sendall_with_error_handle
    sent = self._sock.send(data)
ConnectionResetError: [WinError 10054] An existing connection was forcibly closed by the remote host
2025-06-03 11:10:42,914 ERROR   MainThread:5024 [redirect.py:_on_write():664] [no run ID] error in stderr callback
Traceback (most recent call last):
  File "C:\Anaconda3\envs\AntorchaPy\lib\site-packages\wandb\sdk\lib\redirect.py", line 662, in _on_write
    cb(written_data)
  File "C:\Anaconda3\envs\AntorchaPy\lib\site-packages\wandb\sdk\wandb_run.py", line 2500, in <lambda>
    lambda data: self._console_raw_callback("stderr", data),
  File "C:\Anaconda3\envs\AntorchaPy\lib\site-packages\wandb\sdk\wandb_run.py", line 406, in wrapper
    return func(self, *args, **kwargs)
  File "C:\Anaconda3\envs\AntorchaPy\lib\site-packages\wandb\sdk\wandb_run.py", line 464, in wrapper_fn
    return func(self, *args, **kwargs)
  File "C:\Anaconda3\envs\AntorchaPy\lib\site-packages\wandb\sdk\wandb_run.py", line 1639, in _console_raw_callback
    self._backend.interface.publish_output_raw(name, data)
  File "C:\Anaconda3\envs\AntorchaPy\lib\site-packages\wandb\sdk\interface\interface.py", line 762, in publish_output_raw
    self._publish_output_raw(o)
  File "C:\Anaconda3\envs\AntorchaPy\lib\site-packages\wandb\sdk\interface\interface_shared.py", line 38, in _publish_output_raw
    self._publish(rec)
  File "C:\Anaconda3\envs\AntorchaPy\lib\site-packages\wandb\sdk\interface\interface_sock.py", line 39, in _publish
    self._sock_client.send_record_publish(record)
  File "C:\Anaconda3\envs\AntorchaPy\lib\site-packages\wandb\sdk\lib\sock_client.py", line 174, in send_record_publish
    self.send_server_request(server_req)
  File "C:\Anaconda3\envs\AntorchaPy\lib\site-packages\wandb\sdk\lib\sock_client.py", line 154, in send_server_request
    self._send_message(msg)
  File "C:\Anaconda3\envs\AntorchaPy\lib\site-packages\wandb\sdk\lib\sock_client.py", line 151, in _send_message
    self._sendall_with_error_handle(header + data)
  File "C:\Anaconda3\envs\AntorchaPy\lib\site-packages\wandb\sdk\lib\sock_client.py", line 130, in _sendall_with_error_handle
    sent = self._sock.send(data)
ConnectionResetError: [WinError 10054] An existing connection was forcibly closed by the remote host
2025-06-03 11:10:42,915 ERROR   MainThread:5024 [redirect.py:_on_write():664] [no run ID] error in stderr callback
Traceback (most recent call last):
  File "C:\Anaconda3\envs\AntorchaPy\lib\site-packages\wandb\sdk\lib\redirect.py", line 662, in _on_write
    cb(written_data)
  File "C:\Anaconda3\envs\AntorchaPy\lib\site-packages\wandb\sdk\wandb_run.py", line 2500, in <lambda>
    lambda data: self._console_raw_callback("stderr", data),
  File "C:\Anaconda3\envs\AntorchaPy\lib\site-packages\wandb\sdk\wandb_run.py", line 406, in wrapper
    return func(self, *args, **kwargs)
  File "C:\Anaconda3\envs\AntorchaPy\lib\site-packages\wandb\sdk\wandb_run.py", line 464, in wrapper_fn
    return func(self, *args, **kwargs)
  File "C:\Anaconda3\envs\AntorchaPy\lib\site-packages\wandb\sdk\wandb_run.py", line 1639, in _console_raw_callback
    self._backend.interface.publish_output_raw(name, data)
  File "C:\Anaconda3\envs\AntorchaPy\lib\site-packages\wandb\sdk\interface\interface.py", line 762, in publish_output_raw
    self._publish_output_raw(o)
  File "C:\Anaconda3\envs\AntorchaPy\lib\site-packages\wandb\sdk\interface\interface_shared.py", line 38, in _publish_output_raw
    self._publish(rec)
  File "C:\Anaconda3\envs\AntorchaPy\lib\site-packages\wandb\sdk\interface\interface_sock.py", line 39, in _publish
    self._sock_client.send_record_publish(record)
  File "C:\Anaconda3\envs\AntorchaPy\lib\site-packages\wandb\sdk\lib\sock_client.py", line 174, in send_record_publish
    self.send_server_request(server_req)
  File "C:\Anaconda3\envs\AntorchaPy\lib\site-packages\wandb\sdk\lib\sock_client.py", line 154, in send_server_request
    self._send_message(msg)
  File "C:\Anaconda3\envs\AntorchaPy\lib\site-packages\wandb\sdk\lib\sock_client.py", line 151, in _send_message
    self._sendall_with_error_handle(header + data)
  File "C:\Anaconda3\envs\AntorchaPy\lib\site-packages\wandb\sdk\lib\sock_client.py", line 130, in _sendall_with_error_handle
    sent = self._sock.send(data)
ConnectionResetError: [WinError 10054] An existing connection was forcibly closed by the remote host
2025-06-03 11:10:42,915 ERROR   MainThread:5024 [redirect.py:_on_write():664] [no run ID] error in stderr callback
Traceback (most recent call last):
  File "C:\Anaconda3\envs\AntorchaPy\lib\site-packages\wandb\sdk\lib\redirect.py", line 662, in _on_write
    cb(written_data)
  File "C:\Anaconda3\envs\AntorchaPy\lib\site-packages\wandb\sdk\wandb_run.py", line 2500, in <lambda>
    lambda data: self._console_raw_callback("stderr", data),
  File "C:\Anaconda3\envs\AntorchaPy\lib\site-packages\wandb\sdk\wandb_run.py", line 406, in wrapper
    return func(self, *args, **kwargs)
  File "C:\Anaconda3\envs\AntorchaPy\lib\site-packages\wandb\sdk\wandb_run.py", line 464, in wrapper_fn
    return func(self, *args, **kwargs)
  File "C:\Anaconda3\envs\AntorchaPy\lib\site-packages\wandb\sdk\wandb_run.py", line 1639, in _console_raw_callback
    self._backend.interface.publish_output_raw(name, data)
  File "C:\Anaconda3\envs\AntorchaPy\lib\site-packages\wandb\sdk\interface\interface.py", line 762, in publish_output_raw
    self._publish_output_raw(o)
  File "C:\Anaconda3\envs\AntorchaPy\lib\site-packages\wandb\sdk\interface\interface_shared.py", line 38, in _publish_output_raw
    self._publish(rec)
  File "C:\Anaconda3\envs\AntorchaPy\lib\site-packages\wandb\sdk\interface\interface_sock.py", line 39, in _publish
    self._sock_client.send_record_publish(record)
  File "C:\Anaconda3\envs\AntorchaPy\lib\site-packages\wandb\sdk\lib\sock_client.py", line 174, in send_record_publish
    self.send_server_request(server_req)
  File "C:\Anaconda3\envs\AntorchaPy\lib\site-packages\wandb\sdk\lib\sock_client.py", line 154, in send_server_request
    self._send_message(msg)
  File "C:\Anaconda3\envs\AntorchaPy\lib\site-packages\wandb\sdk\lib\sock_client.py", line 151, in _send_message
    self._sendall_with_error_handle(header + data)
  File "C:\Anaconda3\envs\AntorchaPy\lib\site-packages\wandb\sdk\lib\sock_client.py", line 130, in _sendall_with_error_handle
    sent = self._sock.send(data)
ConnectionResetError: [WinError 10054] An existing connection was forcibly closed by the remote host
2025-06-03 11:10:42,916 ERROR   MainThread:5024 [redirect.py:_on_write():664] [no run ID] error in stderr callback
Traceback (most recent call last):
  File "C:\Anaconda3\envs\AntorchaPy\lib\site-packages\wandb\sdk\lib\redirect.py", line 662, in _on_write
    cb(written_data)
  File "C:\Anaconda3\envs\AntorchaPy\lib\site-packages\wandb\sdk\wandb_run.py", line 2500, in <lambda>
    lambda data: self._console_raw_callback("stderr", data),
  File "C:\Anaconda3\envs\AntorchaPy\lib\site-packages\wandb\sdk\wandb_run.py", line 406, in wrapper
    return func(self, *args, **kwargs)
  File "C:\Anaconda3\envs\AntorchaPy\lib\site-packages\wandb\sdk\wandb_run.py", line 464, in wrapper_fn
    return func(self, *args, **kwargs)
  File "C:\Anaconda3\envs\AntorchaPy\lib\site-packages\wandb\sdk\wandb_run.py", line 1639, in _console_raw_callback
    self._backend.interface.publish_output_raw(name, data)
  File "C:\Anaconda3\envs\AntorchaPy\lib\site-packages\wandb\sdk\interface\interface.py", line 762, in publish_output_raw
    self._publish_output_raw(o)
  File "C:\Anaconda3\envs\AntorchaPy\lib\site-packages\wandb\sdk\interface\interface_shared.py", line 38, in _publish_output_raw
    self._publish(rec)
  File "C:\Anaconda3\envs\AntorchaPy\lib\site-packages\wandb\sdk\interface\interface_sock.py", line 39, in _publish
    self._sock_client.send_record_publish(record)
  File "C:\Anaconda3\envs\AntorchaPy\lib\site-packages\wandb\sdk\lib\sock_client.py", line 174, in send_record_publish
    self.send_server_request(server_req)
  File "C:\Anaconda3\envs\AntorchaPy\lib\site-packages\wandb\sdk\lib\sock_client.py", line 154, in send_server_request
    self._send_message(msg)
  File "C:\Anaconda3\envs\AntorchaPy\lib\site-packages\wandb\sdk\lib\sock_client.py", line 151, in _send_message
    self._sendall_with_error_handle(header + data)
  File "C:\Anaconda3\envs\AntorchaPy\lib\site-packages\wandb\sdk\lib\sock_client.py", line 130, in _sendall_with_error_handle
    sent = self._sock.send(data)
ConnectionResetError: [WinError 10054] An existing connection was forcibly closed by the remote host
2025-06-03 11:10:42,917 ERROR   MainThread:5024 [redirect.py:_on_write():664] [no run ID] error in stderr callback
Traceback (most recent call last):
  File "C:\Anaconda3\envs\AntorchaPy\lib\site-packages\wandb\sdk\lib\redirect.py", line 662, in _on_write
    cb(written_data)
  File "C:\Anaconda3\envs\AntorchaPy\lib\site-packages\wandb\sdk\wandb_run.py", line 2500, in <lambda>
    lambda data: self._console_raw_callback("stderr", data),
  File "C:\Anaconda3\envs\AntorchaPy\lib\site-packages\wandb\sdk\wandb_run.py", line 406, in wrapper
    return func(self, *args, **kwargs)
  File "C:\Anaconda3\envs\AntorchaPy\lib\site-packages\wandb\sdk\wandb_run.py", line 464, in wrapper_fn
    return func(self, *args, **kwargs)
  File "C:\Anaconda3\envs\AntorchaPy\lib\site-packages\wandb\sdk\wandb_run.py", line 1639, in _console_raw_callback
    self._backend.interface.publish_output_raw(name, data)
  File "C:\Anaconda3\envs\AntorchaPy\lib\site-packages\wandb\sdk\interface\interface.py", line 762, in publish_output_raw
    self._publish_output_raw(o)
  File "C:\Anaconda3\envs\AntorchaPy\lib\site-packages\wandb\sdk\interface\interface_shared.py", line 38, in _publish_output_raw
    self._publish(rec)
  File "C:\Anaconda3\envs\AntorchaPy\lib\site-packages\wandb\sdk\interface\interface_sock.py", line 39, in _publish
    self._sock_client.send_record_publish(record)
  File "C:\Anaconda3\envs\AntorchaPy\lib\site-packages\wandb\sdk\lib\sock_client.py", line 174, in send_record_publish
    self.send_server_request(server_req)
  File "C:\Anaconda3\envs\AntorchaPy\lib\site-packages\wandb\sdk\lib\sock_client.py", line 154, in send_server_request
    self._send_message(msg)
  File "C:\Anaconda3\envs\AntorchaPy\lib\site-packages\wandb\sdk\lib\sock_client.py", line 151, in _send_message
    self._sendall_with_error_handle(header + data)
  File "C:\Anaconda3\envs\AntorchaPy\lib\site-packages\wandb\sdk\lib\sock_client.py", line 130, in _sendall_with_error_handle
    sent = self._sock.send(data)
ConnectionResetError: [WinError 10054] An existing connection was forcibly closed by the remote host
2025-06-03 11:10:42,918 ERROR   MainThread:5024 [redirect.py:_on_write():664] [no run ID] error in stderr callback
Traceback (most recent call last):
  File "C:\Anaconda3\envs\AntorchaPy\lib\site-packages\wandb\sdk\lib\redirect.py", line 662, in _on_write
    cb(written_data)
  File "C:\Anaconda3\envs\AntorchaPy\lib\site-packages\wandb\sdk\wandb_run.py", line 2500, in <lambda>
    lambda data: self._console_raw_callback("stderr", data),
  File "C:\Anaconda3\envs\AntorchaPy\lib\site-packages\wandb\sdk\wandb_run.py", line 406, in wrapper
    return func(self, *args, **kwargs)
  File "C:\Anaconda3\envs\AntorchaPy\lib\site-packages\wandb\sdk\wandb_run.py", line 464, in wrapper_fn
    return func(self, *args, **kwargs)
  File "C:\Anaconda3\envs\AntorchaPy\lib\site-packages\wandb\sdk\wandb_run.py", line 1639, in _console_raw_callback
    self._backend.interface.publish_output_raw(name, data)
  File "C:\Anaconda3\envs\AntorchaPy\lib\site-packages\wandb\sdk\interface\interface.py", line 762, in publish_output_raw
    self._publish_output_raw(o)
  File "C:\Anaconda3\envs\AntorchaPy\lib\site-packages\wandb\sdk\interface\interface_shared.py", line 38, in _publish_output_raw
    self._publish(rec)
  File "C:\Anaconda3\envs\AntorchaPy\lib\site-packages\wandb\sdk\interface\interface_sock.py", line 39, in _publish
    self._sock_client.send_record_publish(record)
  File "C:\Anaconda3\envs\AntorchaPy\lib\site-packages\wandb\sdk\lib\sock_client.py", line 174, in send_record_publish
    self.send_server_request(server_req)
  File "C:\Anaconda3\envs\AntorchaPy\lib\site-packages\wandb\sdk\lib\sock_client.py", line 154, in send_server_request
    self._send_message(msg)
  File "C:\Anaconda3\envs\AntorchaPy\lib\site-packages\wandb\sdk\lib\sock_client.py", line 151, in _send_message
    self._sendall_with_error_handle(header + data)
  File "C:\Anaconda3\envs\AntorchaPy\lib\site-packages\wandb\sdk\lib\sock_client.py", line 130, in _sendall_with_error_handle
    sent = self._sock.send(data)
ConnectionResetError: [WinError 10054] An existing connection was forcibly closed by the remote host
2025-06-03 11:10:42,919 ERROR   MainThread:5024 [redirect.py:_on_write():664] [no run ID] error in stderr callback
Traceback (most recent call last):
  File "C:\Anaconda3\envs\AntorchaPy\lib\site-packages\wandb\sdk\lib\redirect.py", line 662, in _on_write
    cb(written_data)
  File "C:\Anaconda3\envs\AntorchaPy\lib\site-packages\wandb\sdk\wandb_run.py", line 2500, in <lambda>
    lambda data: self._console_raw_callback("stderr", data),
  File "C:\Anaconda3\envs\AntorchaPy\lib\site-packages\wandb\sdk\wandb_run.py", line 406, in wrapper
    return func(self, *args, **kwargs)
  File "C:\Anaconda3\envs\AntorchaPy\lib\site-packages\wandb\sdk\wandb_run.py", line 464, in wrapper_fn
    return func(self, *args, **kwargs)
  File "C:\Anaconda3\envs\AntorchaPy\lib\site-packages\wandb\sdk\wandb_run.py", line 1639, in _console_raw_callback
    self._backend.interface.publish_output_raw(name, data)
  File "C:\Anaconda3\envs\AntorchaPy\lib\site-packages\wandb\sdk\interface\interface.py", line 762, in publish_output_raw
    self._publish_output_raw(o)
  File "C:\Anaconda3\envs\AntorchaPy\lib\site-packages\wandb\sdk\interface\interface_shared.py", line 38, in _publish_output_raw
    self._publish(rec)
  File "C:\Anaconda3\envs\AntorchaPy\lib\site-packages\wandb\sdk\interface\interface_sock.py", line 39, in _publish
    self._sock_client.send_record_publish(record)
  File "C:\Anaconda3\envs\AntorchaPy\lib\site-packages\wandb\sdk\lib\sock_client.py", line 174, in send_record_publish
    self.send_server_request(server_req)
  File "C:\Anaconda3\envs\AntorchaPy\lib\site-packages\wandb\sdk\lib\sock_client.py", line 154, in send_server_request
    self._send_message(msg)
  File "C:\Anaconda3\envs\AntorchaPy\lib\site-packages\wandb\sdk\lib\sock_client.py", line 151, in _send_message
    self._sendall_with_error_handle(header + data)
  File "C:\Anaconda3\envs\AntorchaPy\lib\site-packages\wandb\sdk\lib\sock_client.py", line 130, in _sendall_with_error_handle
    sent = self._sock.send(data)
ConnectionResetError: [WinError 10054] An existing connection was forcibly closed by the remote host
2025-06-03 11:10:42,921 ERROR   MainThread:5024 [redirect.py:_on_write():664] [no run ID] error in stderr callback
Traceback (most recent call last):
  File "C:\Anaconda3\envs\AntorchaPy\lib\site-packages\wandb\sdk\lib\redirect.py", line 662, in _on_write
    cb(written_data)
  File "C:\Anaconda3\envs\AntorchaPy\lib\site-packages\wandb\sdk\wandb_run.py", line 2500, in <lambda>
    lambda data: self._console_raw_callback("stderr", data),
  File "C:\Anaconda3\envs\AntorchaPy\lib\site-packages\wandb\sdk\wandb_run.py", line 406, in wrapper
    return func(self, *args, **kwargs)
  File "C:\Anaconda3\envs\AntorchaPy\lib\site-packages\wandb\sdk\wandb_run.py", line 464, in wrapper_fn
    return func(self, *args, **kwargs)
  File "C:\Anaconda3\envs\AntorchaPy\lib\site-packages\wandb\sdk\wandb_run.py", line 1639, in _console_raw_callback
    self._backend.interface.publish_output_raw(name, data)
  File "C:\Anaconda3\envs\AntorchaPy\lib\site-packages\wandb\sdk\interface\interface.py", line 762, in publish_output_raw
    self._publish_output_raw(o)
  File "C:\Anaconda3\envs\AntorchaPy\lib\site-packages\wandb\sdk\interface\interface_shared.py", line 38, in _publish_output_raw
    self._publish(rec)
  File "C:\Anaconda3\envs\AntorchaPy\lib\site-packages\wandb\sdk\interface\interface_sock.py", line 39, in _publish
    self._sock_client.send_record_publish(record)
  File "C:\Anaconda3\envs\AntorchaPy\lib\site-packages\wandb\sdk\lib\sock_client.py", line 174, in send_record_publish
    self.send_server_request(server_req)
  File "C:\Anaconda3\envs\AntorchaPy\lib\site-packages\wandb\sdk\lib\sock_client.py", line 154, in send_server_request
    self._send_message(msg)
  File "C:\Anaconda3\envs\AntorchaPy\lib\site-packages\wandb\sdk\lib\sock_client.py", line 151, in _send_message
    self._sendall_with_error_handle(header + data)
  File "C:\Anaconda3\envs\AntorchaPy\lib\site-packages\wandb\sdk\lib\sock_client.py", line 130, in _sendall_with_error_handle
    sent = self._sock.send(data)
ConnectionResetError: [WinError 10054] An existing connection was forcibly closed by the remote host
2025-06-03 11:10:42,922 ERROR   MainThread:5024 [redirect.py:_on_write():664] [no run ID] error in stderr callback
Traceback (most recent call last):
  File "C:\Anaconda3\envs\AntorchaPy\lib\site-packages\wandb\sdk\lib\redirect.py", line 662, in _on_write
    cb(written_data)
  File "C:\Anaconda3\envs\AntorchaPy\lib\site-packages\wandb\sdk\wandb_run.py", line 2500, in <lambda>
    lambda data: self._console_raw_callback("stderr", data),
  File "C:\Anaconda3\envs\AntorchaPy\lib\site-packages\wandb\sdk\wandb_run.py", line 406, in wrapper
    return func(self, *args, **kwargs)
  File "C:\Anaconda3\envs\AntorchaPy\lib\site-packages\wandb\sdk\wandb_run.py", line 464, in wrapper_fn
    return func(self, *args, **kwargs)
  File "C:\Anaconda3\envs\AntorchaPy\lib\site-packages\wandb\sdk\wandb_run.py", line 1639, in _console_raw_callback
    self._backend.interface.publish_output_raw(name, data)
  File "C:\Anaconda3\envs\AntorchaPy\lib\site-packages\wandb\sdk\interface\interface.py", line 762, in publish_output_raw
    self._publish_output_raw(o)
  File "C:\Anaconda3\envs\AntorchaPy\lib\site-packages\wandb\sdk\interface\interface_shared.py", line 38, in _publish_output_raw
    self._publish(rec)
  File "C:\Anaconda3\envs\AntorchaPy\lib\site-packages\wandb\sdk\interface\interface_sock.py", line 39, in _publish
    self._sock_client.send_record_publish(record)
  File "C:\Anaconda3\envs\AntorchaPy\lib\site-packages\wandb\sdk\lib\sock_client.py", line 174, in send_record_publish
    self.send_server_request(server_req)
  File "C:\Anaconda3\envs\AntorchaPy\lib\site-packages\wandb\sdk\lib\sock_client.py", line 154, in send_server_request
    self._send_message(msg)
  File "C:\Anaconda3\envs\AntorchaPy\lib\site-packages\wandb\sdk\lib\sock_client.py", line 151, in _send_message
    self._sendall_with_error_handle(header + data)
  File "C:\Anaconda3\envs\AntorchaPy\lib\site-packages\wandb\sdk\lib\sock_client.py", line 130, in _sendall_with_error_handle
    sent = self._sock.send(data)
ConnectionResetError: [WinError 10054] An existing connection was forcibly closed by the remote host
2025-06-03 11:10:42,923 ERROR   MainThread:5024 [redirect.py:_on_write():664] [no run ID] error in stderr callback
Traceback (most recent call last):
  File "C:\Anaconda3\envs\AntorchaPy\lib\site-packages\wandb\sdk\lib\redirect.py", line 662, in _on_write
    cb(written_data)
  File "C:\Anaconda3\envs\AntorchaPy\lib\site-packages\wandb\sdk\wandb_run.py", line 2500, in <lambda>
    lambda data: self._console_raw_callback("stderr", data),
  File "C:\Anaconda3\envs\AntorchaPy\lib\site-packages\wandb\sdk\wandb_run.py", line 406, in wrapper
    return func(self, *args, **kwargs)
  File "C:\Anaconda3\envs\AntorchaPy\lib\site-packages\wandb\sdk\wandb_run.py", line 464, in wrapper_fn
    return func(self, *args, **kwargs)
  File "C:\Anaconda3\envs\AntorchaPy\lib\site-packages\wandb\sdk\wandb_run.py", line 1639, in _console_raw_callback
    self._backend.interface.publish_output_raw(name, data)
  File "C:\Anaconda3\envs\AntorchaPy\lib\site-packages\wandb\sdk\interface\interface.py", line 762, in publish_output_raw
    self._publish_output_raw(o)
  File "C:\Anaconda3\envs\AntorchaPy\lib\site-packages\wandb\sdk\interface\interface_shared.py", line 38, in _publish_output_raw
    self._publish(rec)
  File "C:\Anaconda3\envs\AntorchaPy\lib\site-packages\wandb\sdk\interface\interface_sock.py", line 39, in _publish
    self._sock_client.send_record_publish(record)
  File "C:\Anaconda3\envs\AntorchaPy\lib\site-packages\wandb\sdk\lib\sock_client.py", line 174, in send_record_publish
    self.send_server_request(server_req)
  File "C:\Anaconda3\envs\AntorchaPy\lib\site-packages\wandb\sdk\lib\sock_client.py", line 154, in send_server_request
    self._send_message(msg)
  File "C:\Anaconda3\envs\AntorchaPy\lib\site-packages\wandb\sdk\lib\sock_client.py", line 151, in _send_message
    self._sendall_with_error_handle(header + data)
  File "C:\Anaconda3\envs\AntorchaPy\lib\site-packages\wandb\sdk\lib\sock_client.py", line 130, in _sendall_with_error_handle
    sent = self._sock.send(data)
ConnectionResetError: [WinError 10054] An existing connection was forcibly closed by the remote host
2025-06-03 11:10:42,923 ERROR   MainThread:5024 [redirect.py:_on_write():664] [no run ID] error in stderr callback
Traceback (most recent call last):
  File "C:\Anaconda3\envs\AntorchaPy\lib\site-packages\wandb\sdk\lib\redirect.py", line 662, in _on_write
    cb(written_data)
  File "C:\Anaconda3\envs\AntorchaPy\lib\site-packages\wandb\sdk\wandb_run.py", line 2500, in <lambda>
    lambda data: self._console_raw_callback("stderr", data),
  File "C:\Anaconda3\envs\AntorchaPy\lib\site-packages\wandb\sdk\wandb_run.py", line 406, in wrapper
    return func(self, *args, **kwargs)
  File "C:\Anaconda3\envs\AntorchaPy\lib\site-packages\wandb\sdk\wandb_run.py", line 464, in wrapper_fn
    return func(self, *args, **kwargs)
  File "C:\Anaconda3\envs\AntorchaPy\lib\site-packages\wandb\sdk\wandb_run.py", line 1639, in _console_raw_callback
    self._backend.interface.publish_output_raw(name, data)
  File "C:\Anaconda3\envs\AntorchaPy\lib\site-packages\wandb\sdk\interface\interface.py", line 762, in publish_output_raw
    self._publish_output_raw(o)
  File "C:\Anaconda3\envs\AntorchaPy\lib\site-packages\wandb\sdk\interface\interface_shared.py", line 38, in _publish_output_raw
    self._publish(rec)
  File "C:\Anaconda3\envs\AntorchaPy\lib\site-packages\wandb\sdk\interface\interface_sock.py", line 39, in _publish
    self._sock_client.send_record_publish(record)
  File "C:\Anaconda3\envs\AntorchaPy\lib\site-packages\wandb\sdk\lib\sock_client.py", line 174, in send_record_publish
    self.send_server_request(server_req)
  File "C:\Anaconda3\envs\AntorchaPy\lib\site-packages\wandb\sdk\lib\sock_client.py", line 154, in send_server_request
    self._send_message(msg)
  File "C:\Anaconda3\envs\AntorchaPy\lib\site-packages\wandb\sdk\lib\sock_client.py", line 151, in _send_message
    self._sendall_with_error_handle(header + data)
  File "C:\Anaconda3\envs\AntorchaPy\lib\site-packages\wandb\sdk\lib\sock_client.py", line 130, in _sendall_with_error_handle
    sent = self._sock.send(data)
ConnectionResetError: [WinError 10054] An existing connection was forcibly closed by the remote host
2025-06-03 11:10:42,924 ERROR   MainThread:5024 [redirect.py:_on_write():664] [no run ID] error in stderr callback
Traceback (most recent call last):
  File "C:\Anaconda3\envs\AntorchaPy\lib\site-packages\wandb\sdk\lib\redirect.py", line 662, in _on_write
    cb(written_data)
  File "C:\Anaconda3\envs\AntorchaPy\lib\site-packages\wandb\sdk\wandb_run.py", line 2500, in <lambda>
    lambda data: self._console_raw_callback("stderr", data),
  File "C:\Anaconda3\envs\AntorchaPy\lib\site-packages\wandb\sdk\wandb_run.py", line 406, in wrapper
    return func(self, *args, **kwargs)
  File "C:\Anaconda3\envs\AntorchaPy\lib\site-packages\wandb\sdk\wandb_run.py", line 464, in wrapper_fn
    return func(self, *args, **kwargs)
  File "C:\Anaconda3\envs\AntorchaPy\lib\site-packages\wandb\sdk\wandb_run.py", line 1639, in _console_raw_callback
    self._backend.interface.publish_output_raw(name, data)
  File "C:\Anaconda3\envs\AntorchaPy\lib\site-packages\wandb\sdk\interface\interface.py", line 762, in publish_output_raw
    self._publish_output_raw(o)
  File "C:\Anaconda3\envs\AntorchaPy\lib\site-packages\wandb\sdk\interface\interface_shared.py", line 38, in _publish_output_raw
    self._publish(rec)
  File "C:\Anaconda3\envs\AntorchaPy\lib\site-packages\wandb\sdk\interface\interface_sock.py", line 39, in _publish
    self._sock_client.send_record_publish(record)
  File "C:\Anaconda3\envs\AntorchaPy\lib\site-packages\wandb\sdk\lib\sock_client.py", line 174, in send_record_publish
    self.send_server_request(server_req)
  File "C:\Anaconda3\envs\AntorchaPy\lib\site-packages\wandb\sdk\lib\sock_client.py", line 154, in send_server_request
    self._send_message(msg)
  File "C:\Anaconda3\envs\AntorchaPy\lib\site-packages\wandb\sdk\lib\sock_client.py", line 151, in _send_message
    self._sendall_with_error_handle(header + data)
  File "C:\Anaconda3\envs\AntorchaPy\lib\site-packages\wandb\sdk\lib\sock_client.py", line 130, in _sendall_with_error_handle
    sent = self._sock.send(data)
ConnectionResetError: [WinError 10054] An existing connection was forcibly closed by the remote host
2025-06-03 11:10:42,925 ERROR   MainThread:5024 [redirect.py:_on_write():664] [no run ID] error in stderr callback
Traceback (most recent call last):
  File "C:\Anaconda3\envs\AntorchaPy\lib\site-packages\wandb\sdk\lib\redirect.py", line 662, in _on_write
    cb(written_data)
  File "C:\Anaconda3\envs\AntorchaPy\lib\site-packages\wandb\sdk\wandb_run.py", line 2500, in <lambda>
    lambda data: self._console_raw_callback("stderr", data),
  File "C:\Anaconda3\envs\AntorchaPy\lib\site-packages\wandb\sdk\wandb_run.py", line 406, in wrapper
    return func(self, *args, **kwargs)
  File "C:\Anaconda3\envs\AntorchaPy\lib\site-packages\wandb\sdk\wandb_run.py", line 464, in wrapper_fn
    return func(self, *args, **kwargs)
  File "C:\Anaconda3\envs\AntorchaPy\lib\site-packages\wandb\sdk\wandb_run.py", line 1639, in _console_raw_callback
    self._backend.interface.publish_output_raw(name, data)
  File "C:\Anaconda3\envs\AntorchaPy\lib\site-packages\wandb\sdk\interface\interface.py", line 762, in publish_output_raw
    self._publish_output_raw(o)
  File "C:\Anaconda3\envs\AntorchaPy\lib\site-packages\wandb\sdk\interface\interface_shared.py", line 38, in _publish_output_raw
    self._publish(rec)
  File "C:\Anaconda3\envs\AntorchaPy\lib\site-packages\wandb\sdk\interface\interface_sock.py", line 39, in _publish
    self._sock_client.send_record_publish(record)
  File "C:\Anaconda3\envs\AntorchaPy\lib\site-packages\wandb\sdk\lib\sock_client.py", line 174, in send_record_publish
    self.send_server_request(server_req)
  File "C:\Anaconda3\envs\AntorchaPy\lib\site-packages\wandb\sdk\lib\sock_client.py", line 154, in send_server_request
    self._send_message(msg)
  File "C:\Anaconda3\envs\AntorchaPy\lib\site-packages\wandb\sdk\lib\sock_client.py", line 151, in _send_message
    self._sendall_with_error_handle(header + data)
  File "C:\Anaconda3\envs\AntorchaPy\lib\site-packages\wandb\sdk\lib\sock_client.py", line 130, in _sendall_with_error_handle
    sent = self._sock.send(data)
ConnectionResetError: [WinError 10054] An existing connection was forcibly closed by the remote host
2025-06-03 11:10:42,926 ERROR   MainThread:5024 [redirect.py:_on_write():664] [no run ID] error in stderr callback
Traceback (most recent call last):
  File "C:\Anaconda3\envs\AntorchaPy\lib\site-packages\wandb\sdk\lib\redirect.py", line 662, in _on_write
    cb(written_data)
  File "C:\Anaconda3\envs\AntorchaPy\lib\site-packages\wandb\sdk\wandb_run.py", line 2500, in <lambda>
    lambda data: self._console_raw_callback("stderr", data),
  File "C:\Anaconda3\envs\AntorchaPy\lib\site-packages\wandb\sdk\wandb_run.py", line 406, in wrapper
    return func(self, *args, **kwargs)
  File "C:\Anaconda3\envs\AntorchaPy\lib\site-packages\wandb\sdk\wandb_run.py", line 464, in wrapper_fn
    return func(self, *args, **kwargs)
  File "C:\Anaconda3\envs\AntorchaPy\lib\site-packages\wandb\sdk\wandb_run.py", line 1639, in _console_raw_callback
    self._backend.interface.publish_output_raw(name, data)
  File "C:\Anaconda3\envs\AntorchaPy\lib\site-packages\wandb\sdk\interface\interface.py", line 762, in publish_output_raw
    self._publish_output_raw(o)
  File "C:\Anaconda3\envs\AntorchaPy\lib\site-packages\wandb\sdk\interface\interface_shared.py", line 38, in _publish_output_raw
    self._publish(rec)
  File "C:\Anaconda3\envs\AntorchaPy\lib\site-packages\wandb\sdk\interface\interface_sock.py", line 39, in _publish
    self._sock_client.send_record_publish(record)
  File "C:\Anaconda3\envs\AntorchaPy\lib\site-packages\wandb\sdk\lib\sock_client.py", line 174, in send_record_publish
    self.send_server_request(server_req)
  File "C:\Anaconda3\envs\AntorchaPy\lib\site-packages\wandb\sdk\lib\sock_client.py", line 154, in send_server_request
    self._send_message(msg)
  File "C:\Anaconda3\envs\AntorchaPy\lib\site-packages\wandb\sdk\lib\sock_client.py", line 151, in _send_message
    self._sendall_with_error_handle(header + data)
  File "C:\Anaconda3\envs\AntorchaPy\lib\site-packages\wandb\sdk\lib\sock_client.py", line 130, in _sendall_with_error_handle
    sent = self._sock.send(data)
ConnectionResetError: [WinError 10054] An existing connection was forcibly closed by the remote host
